<sdf version='1.9'>
  <model name='levibot'>
    <link name='base_link'>
      <inertial>
        <pose>0.0006916996047430832 0 0.0003557312252964427 0 0 0</pose>
        <mass>1.012</mass>
        <inertia>
          <ixx>0.001145071936758893</ixx>
          <ixy>0</ixy>
          <ixz>-2.0750988142292491e-05</ixz>
          <iyy>0.0055896814970355733</iyy>
          <iyz>0</iyz>
          <izz>0.0061126595602766813</izz>
        </inertia>
      </inertial>
      <collision name='base_link_fixed_joint_lump__chassis_collision'>
        <pose>0 0 0 0 0 0</pose>
        <geometry>
          <box>
            <size>0.25 0.1 0.06</size>
          </box>
        </geometry>
        <surface>
          <contact>
            <ode/>
          </contact>
          <friction>
            <ode/>
          </friction>
        </surface>
      </collision>
      <collision name='base_link_fixed_joint_lump__imu_link_collision_1'>
        <pose>0 0 0.03 0 0 0</pose>
        <geometry>
          <box>
            <size>0.025 0.02 0.005</size>
          </box>
        </geometry>
      </collision>
      <collision name='base_link_fixed_joint_lump__lidar_link_collision_2'>
        <pose>0.1 0 0.03 0 0 0</pose>
        <geometry>
          <box>
            <size>0.03 0.03 0.025</size>
          </box>
        </geometry>
        <surface>
          <contact>
            <ode/>
          </contact>
          <friction>
            <ode/>
          </friction>
        </surface>
      </collision>
      <visual name='base_link_fixed_joint_lump__chassis_visual'>
        <pose>0 0 0 0 0 0</pose>
        <geometry>
          <box>
            <size>0.25 0.1 0.06</size>
          </box>
        </geometry>
        <material>
          <script>
            <name>Gazebo/Blue</name>
            <uri>file://media/materials/scripts/gazebo.material</uri>
          </script>
          <diffuse>0 0 1 1</diffuse>
          <ambient>0 0 1 1</ambient>
        </material>
      </visual>
      <visual name='base_link_fixed_joint_lump__imu_link_visual_1'>
        <pose>0 0 0.03 0 0 0</pose>
        <geometry>
          <box>
            <size>0.025 0.02 0.005</size>
          </box>
        </geometry>
        <material>
          <diffuse>1 1 1 1</diffuse>
          <ambient>1 1 1 1</ambient>
        </material>
      </visual>
      <visual name='base_link_fixed_joint_lump__lidar_link_visual_2'>
        <pose>0.1 0 0.03 0 0 0</pose>
        <geometry>
          <box>
            <size>0.03 0.03 0.025</size>
          </box>
        </geometry>
        <material>
          <diffuse>1 0 0 1</diffuse>
          <ambient>1 0 0 1</ambient>
        </material>
      </visual>
      <sensor name='lidar_sensor' type='gpu_lidar'>
        <topic>scan</topic>
        <update_rate>10</update_rate>
        <lidar>
          <scan>
            <horizontal>
              <samples>640</samples>
              <resolution>1</resolution>
              <min_angle>-1.396263</min_angle>
              <max_angle>1.396263</max_angle>
            </horizontal>
            <vertical>
              <samples>1</samples>
              <resolution>1</resolution>
              <min_angle>0</min_angle>
              <max_angle>0</max_angle>
            </vertical>
          </scan>
          <range>
            <min>0.080000000000000002</min>
            <max>10</max>
            <resolution>0.01</resolution>
          </range>
        </lidar>
        <visualize>true</visualize>
        <pose>0.1 0 0.03 0 -0 0</pose>
      </sensor>
    </link>
    <joint name='fl_wheel_joint' type='revolute'>
      <pose relative_to='base_link'>0.06 0.065 -0.035 -1.570796326794896 0 0</pose>
      <parent>base_link</parent>
      <child>fl_wheel_link</child>
      <axis>
        <xyz>0 0 1</xyz>
        <limit>
          <lower>-10000000000000000</lower>
          <upper>10000000000000000</upper>
        </limit>
        <dynamics>
          <spring_reference>0</spring_reference>
          <spring_stiffness>0</spring_stiffness>
        </dynamics>
      </axis>
    </joint>
    <link name='fl_wheel_link'>
      <pose relative_to='fl_wheel_joint'>0 0 0 0 0 0</pose>
      <inertial>
        <pose>0 0 0 0 0 0</pose>
        <mass>0.10000000000000001</mass>
        <inertia>
          <ixx>2.770833333333333e-05</ixx>
          <ixy>0</ixy>
          <ixz>0</ixz>
          <iyy>2.770833333333333e-05</iyy>
          <iyz>0</iyz>
          <izz>4.5000000000000003e-05</izz>
        </inertia>
      </inertial>
      <collision name='fl_wheel_link_collision'>
        <pose>0 0 0 0 0 0</pose>
        <geometry>
          <cylinder>
            <length>0.025000000000000001</length>
            <radius>0.029999999999999999</radius>
          </cylinder>
        </geometry>
        <surface>
          <contact>
            <ode/>
          </contact>
          <friction>
            <ode>
              <mu>0.20000000000000001</mu>
              <mu2>0.20000000000000001</mu2>
            </ode>
          </friction>
        </surface>
      </collision>
      <visual name='fl_wheel_link_visual'>
        <pose>0 0 0 0 0 0</pose>
        <geometry>
          <cylinder>
            <length>0.025000000000000001</length>
            <radius>0.029999999999999999</radius>
          </cylinder>
        </geometry>
        <material>
          <script>
            <name>Gazebo/Green</name>
            <uri>file://media/materials/scripts/gazebo.material</uri>
          </script>
          <diffuse>0 1 0 1</diffuse>
          <ambient>0 1 0 1</ambient>
        </material>
      </visual>
    </link>
    <joint name='fr_wheel_joint' type='revolute'>
      <pose relative_to='base_link'>0.06 -0.065 -0.035 1.570796326794896 0 0</pose>
      <parent>base_link</parent>
      <child>fr_wheel_link</child>
      <axis>
        <xyz>0 0 -1</xyz>
        <limit>
          <lower>-10000000000000000</lower>
          <upper>10000000000000000</upper>
        </limit>
        <dynamics>
          <spring_reference>0</spring_reference>
          <spring_stiffness>0</spring_stiffness>
        </dynamics>
      </axis>
    </joint>
    <link name='fr_wheel_link'>
      <pose relative_to='fr_wheel_joint'>0 0 0 0 0 0</pose>
      <inertial>
        <pose>0 0 0 0 0 0</pose>
        <mass>0.10000000000000001</mass>
        <inertia>
          <ixx>2.770833333333333e-05</ixx>
          <ixy>0</ixy>
          <ixz>0</ixz>
          <iyy>2.770833333333333e-05</iyy>
          <iyz>0</iyz>
          <izz>4.5000000000000003e-05</izz>
        </inertia>
      </inertial>
      <collision name='fr_wheel_link_collision'>
        <pose>0 0 0 0 0 0</pose>
        <geometry>
          <cylinder>
            <length>0.025000000000000001</length>
            <radius>0.029999999999999999</radius>
          </cylinder>
        </geometry>
        <surface>
          <contact>
            <ode/>
          </contact>
          <friction>
            <ode>
              <mu>0.20000000000000001</mu>
              <mu2>0.20000000000000001</mu2>
            </ode>
          </friction>
        </surface>
      </collision>
      <visual name='fr_wheel_link_visual'>
        <pose>0 0 0 0 0 0</pose>
        <geometry>
          <cylinder>
            <length>0.025000000000000001</length>
            <radius>0.029999999999999999</radius>
          </cylinder>
        </geometry>
        <material>
          <script>
            <name>Gazebo/Green</name>
            <uri>file://media/materials/scripts/gazebo.material</uri>
          </script>
          <diffuse>0 1 0 1</diffuse>
          <ambient>0 1 0 1</ambient>
        </material>
      </visual>
    </link>
    <joint name='rl_wheel_joint' type='revolute'>
      <pose relative_to='base_link'>-0.06 0.065 -0.035 -1.570796326794896 0 0</pose>
      <parent>base_link</parent>
      <child>rl_wheel_link</child>
      <axis>
        <xyz>0 0 1</xyz>
        <limit>
          <lower>-10000000000000000</lower>
          <upper>10000000000000000</upper>
        </limit>
        <dynamics>
          <spring_reference>0</spring_reference>
          <spring_stiffness>0</spring_stiffness>
        </dynamics>
      </axis>
    </joint>
    <link name='rl_wheel_link'>
      <pose relative_to='rl_wheel_joint'>0 0 0 0 0 0</pose>
      <inertial>
        <pose>0 0 0 0 0 0</pose>
        <mass>0.10000000000000001</mass>
        <inertia>
          <ixx>2.770833333333333e-05</ixx>
          <ixy>0</ixy>
          <ixz>0</ixz>
          <iyy>2.770833333333333e-05</iyy>
          <iyz>0</iyz>
          <izz>4.5000000000000003e-05</izz>
        </inertia>
      </inertial>
      <collision name='rl_wheel_link_collision'>
        <pose>0 0 0 0 0 0</pose>
        <geometry>
          <cylinder>
            <length>0.025000000000000001</length>
            <radius>0.029999999999999999</radius>
          </cylinder>
        </geometry>
        <surface>
          <contact>
            <ode/>
          </contact>
          <friction>
            <ode>
              <mu>0.20000000000000001</mu>
              <mu2>0.20000000000000001</mu2>
            </ode>
          </friction>
        </surface>
      </collision>
      <visual name='rl_wheel_link_visual'>
        <pose>0 0 0 0 0 0</pose>
        <geometry>
          <cylinder>
            <length>0.025000000000000001</length>
            <radius>0.029999999999999999</radius>
          </cylinder>
        </geometry>
        <material>
          <script>
            <name>Gazebo/Green</name>
            <uri>file://media/materials/scripts/gazebo.material</uri>
          </script>
          <diffuse>0 1 0 1</diffuse>
          <ambient>0 1 0 1</ambient>
        </material>
      </visual>
    </link>
    <joint name='rr_wheel_joint' type='revolute'>
      <pose relative_to='base_link'>-0.06 -0.065 -0.035 1.570796326794896 0 0</pose>
      <parent>base_link</parent>
      <child>rr_wheel_link</child>
      <axis>
        <xyz>0 0 -1</xyz>
        <limit>
          <lower>-10000000000000000</lower>
          <upper>10000000000000000</upper>
        </limit>
        <dynamics>
          <spring_reference>0</spring_reference>
          <spring_stiffness>0</spring_stiffness>
        </dynamics>
      </axis>
    </joint>
    <link name='rr_wheel_link'>
      <pose relative_to='rr_wheel_joint'>0 0 0 0 0 0</pose>
      <inertial>
        <pose>0 0 0 0 0 0</pose>
        <mass>0.10000000000000001</mass>
        <inertia>
          <ixx>2.770833333333333e-05</ixx>
          <ixy>0</ixy>
          <ixz>0</ixz>
          <iyy>2.770833333333333e-05</iyy>
          <iyz>0</iyz>
          <izz>4.5000000000000003e-05</izz>
        </inertia>
      </inertial>
      <collision name='rr_wheel_link_collision'>
        <pose>0 0 0 0 0 0</pose>
        <geometry>
          <cylinder>
            <length>0.025000000000000001</length>
            <radius>0.029999999999999999</radius>
          </cylinder>
        </geometry>
        <surface>
          <contact>
            <ode/>
          </contact>
          <friction>
            <ode>
              <mu>0.20000000000000001</mu>
              <mu2>0.20000000000000001</mu2>
            </ode>
          </friction>
        </surface>
      </collision>
      <visual name='rr_wheel_link_visual'>
        <pose>0 0 0 0 0 0</pose>
        <geometry>
          <cylinder>
            <length>0.025000000000000001</length>
            <radius>0.029999999999999999</radius>
          </cylinder>
        </geometry>
        <material>
          <script>
            <name>Gazebo/Green</name>
            <uri>file://media/materials/scripts/gazebo.material</uri>
          </script>
          <diffuse>0 1 0 1</diffuse>
          <ambient>0 1 0 1</ambient>
        </material>
      </visual>
    </link>
    <plugin name='gz_ros2_control::GazeboSimROS2ControlPlugin' filename='libgz_ros2_control-system.so'>
      <parameters>/home/sayed/ros_rolling_ws/src/levibot/levibot_skidsteer/simulation/config/gz_controllers.yaml</parameters>
      <controller_manager_prefix_node_name>controller_manager</controller_manager_prefix_node_name>
      <ros>
        <remapping>/base_controller/cmd_vel_unstamped:=/cmd_vel</remapping>
        <remapping>/base_controller/odom:=/odom</remapping>
      </ros>
    </plugin>
    <frame name='chassis_joint' attached_to='base_link'>
      <pose>0 0 0 0 -0 0</pose>
    </frame>
    <frame name='chassis' attached_to='chassis_joint'/>
    <frame name='imu_joint' attached_to='base_link'>
      <pose>0 0 0.03 0 -0 0</pose>
    </frame>
    <frame name='imu_link' attached_to='imu_joint'/>
    <frame name='lidar_joint' attached_to='base_link'>
      <pose>0.1 0 0.03 0 -0 0</pose>
    </frame>
    <frame name='lidar_link' attached_to='lidar_joint'/>
  </model>
</sdf>
