<?xml version="1.0" ?>
<!-- =================================================================================== -->
<!-- |    This document was autogenerated by xacro from levibot.urdf.xacro             | -->
<!-- |    EDITING THIS FILE BY HAND IS NOT RECOMMENDED                                 | -->
<!-- =================================================================================== -->
<robot name="levibot">
  <material name="black">
    <color rgba="0 0 0 1"/>
  </material>
  <material name="grey">
    <color rgba="0.5 0.5 0.5 1"/>
  </material>
  <material name="white">
    <color rgba="1 1 1 1"/>
  </material>
  <material name="red">
    <color rgba="1 0 0 1"/>
  </material>
  <material name="green">
    <color rgba="0 1 0 1"/>
  </material>
  <material name="blue">
    <color rgba="0 0 1 1"/>
  </material>
  <!-- =============== Links & Joints =============== -->
  <link name="base_link"/>
  <!-- Chassis Link  -->
  <joint name="chassis_joint" type="fixed">
    <parent link="base_link"/>
    <child link="chassis"/>
    <origin rpy="0.0 0.0 0.0" xyz="0.0 0.0 0.0"/>
  </joint>
  <link name="chassis">
    <visual>
      <origin rpy="0 0 0" xyz="0 0 0"/>
      <geometry>
        <box size="0.25 0.10 0.06"/>
      </geometry>
      <material name="blue"/>
    </visual>
    <collision>
      <geometry>
        <box size="0.25 0.10 0.06"/>
      </geometry>
    </collision>
    <inertial>
      <origin rpy="0 0 0" xyz="0 0 0"/>
      <mass value="1.0"/>
      <inertia ixx="0.0011333333333333334" ixy="0.0" ixz="0.0" iyy="0.005508333333333334" iyz="0.0" izz="0.006041666666666667"/>
    </inertial>
  </link>
  <!-- Front Right Wheel Link -->
  <joint name="fr_wheel_joint" type="continuous">
    <origin rpy="1.5707963267948966 0 0" xyz="0.06 -0.065 -0.035"/>
    <parent link="base_link"/>
    <child link="fr_wheel_link"/>
    <axis xyz="0 0 -1"/>
  </joint>
  <link name="fr_wheel_link">
    <visual>
      <origin rpy="0.0 0.0 0.0" xyz="0.0 0.0 0.0"/>
      <geometry>
        <cylinder length="0.025" radius="0.03"/>
      </geometry>
      <material name="green"/>
    </visual>
    <collision>
      <origin rpy="0.0 0.0 0.0" xyz="0.0 0.0 0.0"/>
      <geometry>
        <cylinder length="0.025" radius="0.03"/>
      </geometry>
    </collision>
    <inertial>
      <origin rpy="0 0 0" xyz="0 0 0"/>
      <mass value="0.1"/>
      <inertia ixx="2.770833333333333e-05" ixy="0.0" ixz="0.0" iyy="2.770833333333333e-05" iyz="0.0" izz="4.5e-05"/>
    </inertial>
  </link>
  <!-- Front left Wheel Link -->
  <joint name="fl_wheel_joint" type="continuous">
    <origin rpy="-1.5707963267948966 0 0" xyz="0.06 0.065 -0.035"/>
    <parent link="base_link"/>
    <child link="fl_wheel_link"/>
    <axis xyz="0 0 1"/>
  </joint>
  <link name="fl_wheel_link">
    <visual>
      <origin rpy="0.0 0.0 0.0" xyz="0.0 0.0 0.0"/>
      <geometry>
        <cylinder length="0.025" radius="0.03"/>
      </geometry>
      <material name="green"/>
    </visual>
    <collision>
      <origin rpy="0.0 0.0 0.0" xyz="0.0 0.0 0.0"/>
      <geometry>
        <cylinder length="0.025" radius="0.03"/>
      </geometry>
    </collision>
    <inertial>
      <origin rpy="0 0 0" xyz="0 0 0"/>
      <mass value="0.1"/>
      <inertia ixx="2.770833333333333e-05" ixy="0.0" ixz="0.0" iyy="2.770833333333333e-05" iyz="0.0" izz="4.5e-05"/>
    </inertial>
  </link>
  <!-- Rare Right Wheel Link -->
  <joint name="rr_wheel_joint" type="continuous">
    <origin rpy="1.5707963267948966 0 0" xyz="-0.06 -0.065 -0.035"/>
    <parent link="base_link"/>
    <child link="rr_wheel_link"/>
    <axis xyz="0 0 -1"/>
  </joint>
  <link name="rr_wheel_link">
    <visual>
      <origin rpy="0.0 0.0 0.0" xyz="0.0 0.0 0.0"/>
      <geometry>
        <cylinder length="0.025" radius="0.03"/>
      </geometry>
      <material name="green"/>
    </visual>
    <collision>
      <origin rpy="0.0 0.0 0.0" xyz="0.0 0.0 0.0"/>
      <geometry>
        <cylinder length="0.025" radius="0.03"/>
      </geometry>
    </collision>
    <inertial>
      <origin rpy="0 0 0" xyz="0 0 0"/>
      <mass value="0.1"/>
      <inertia ixx="2.770833333333333e-05" ixy="0.0" ixz="0.0" iyy="2.770833333333333e-05" iyz="0.0" izz="4.5e-05"/>
    </inertial>
  </link>
  <!-- Rare left Wheel Link -->
  <joint name="rl_wheel_joint" type="continuous">
    <origin rpy="-1.5707963267948966 0 0" xyz="-0.06 0.065 -0.035"/>
    <parent link="base_link"/>
    <child link="rl_wheel_link"/>
    <axis xyz="0 0 1"/>
  </joint>
  <link name="rl_wheel_link">
    <visual>
      <origin rpy="0.0 0.0 0.0" xyz="0.0 0.0 0.0"/>
      <geometry>
        <cylinder length="0.025" radius="0.03"/>
      </geometry>
      <material name="green"/>
    </visual>
    <collision>
      <origin rpy="0.0 0.0 0.0" xyz="0.0 0.0 0.0"/>
      <geometry>
        <cylinder length="0.025" radius="0.03"/>
      </geometry>
    </collision>
    <inertial>
      <origin rpy="0 0 0" xyz="0 0 0"/>
      <mass value="0.1"/>
      <inertia ixx="2.770833333333333e-05" ixy="0.0" ixz="0.0" iyy="2.770833333333333e-05" iyz="0.0" izz="4.5e-05"/>
    </inertial>
  </link>
  <!-- Sensors -->
  <!-- IMU Link -->
  <joint name="imu_joint" type="fixed">
    <origin rpy="0.0 0.0 0.0" xyz="0.0 0.0 0.03"/>
    <parent link="base_link"/>
    <child link="imu_link"/>
  </joint>
  <link name="imu_link">
    <collision>
      <geometry>
        <box size="0.025 0.02 0.005"/>
      </geometry>
    </collision>
    <visual>
      <geometry>
        <box size="0.025 0.02 0.005"/>
      </geometry>
      <material name="white"/>
    </visual>
    <inertial>
      <origin rpy="0 0 0" xyz="0 0 0"/>
      <mass value="0.005"/>
      <inertia ixx="1.7708333333333334e-07" ixy="0.0" ixz="0.0" iyy="2.7083333333333337e-07" iyz="0.0" izz="4.2708333333333336e-07"/>
    </inertial>
  </link>
  <!-- LIDAR Link -->
  <joint name="lidar_joint" type="fixed">
    <origin rpy="0.0 0.0 0.0" xyz="0.1 0.0 0.03"/>
    <parent link="base_link"/>
    <child link="lidar_link"/>
  </joint>
  <link name="lidar_link">
    <collision>
      <geometry>
        <box size="0.03 0.03 0.025"/>
      </geometry>
    </collision>
    <visual>
      <geometry>
        <box size="0.03 0.03 0.025"/>
      </geometry>
      <material name="red"/>
    </visual>
    <inertial>
      <origin rpy="0 0 0" xyz="0 0 0"/>
      <mass value="0.007"/>
      <inertia ixx="8.895833333333333e-07" ixy="0.0" ixz="0.0" iyy="8.895833333333333e-07" iyz="0.0" izz="1.05e-06"/>
    </inertial>
  </link>
  <ros2_control name="levibot" type="system">
    <hardware>
      <plugin>gz_ros2_control/GazeboSimSystem</plugin>
    </hardware>
    <!-- Joints -->
    <joint name="fl_wheel_joint">
      <command_interface name="velocity">
        <param name="min">-1</param>
        <param name="max">1</param>
      </command_interface>
      <state_interface name="velocity"/>
      <state_interface name="position"/>
    </joint>
    <joint name="fr_wheel_joint">
      <command_interface name="velocity">
        <param name="min">-1</param>
        <param name="max">1</param>
      </command_interface>
      <state_interface name="velocity"/>
      <state_interface name="position"/>
    </joint>
    <joint name="rl_wheel_joint">
      <command_interface name="velocity">
        <param name="min">-1</param>
        <param name="max">1</param>
      </command_interface>
      <state_interface name="velocity"/>
      <state_interface name="position"/>
    </joint>
    <joint name="rr_wheel_joint">
      <command_interface name="velocity">
        <param name="min">-1</param>
        <param name="max">1</param>
      </command_interface>
      <state_interface name="velocity"/>
      <state_interface name="position"/>
    </joint>
  </ros2_control>
  <gazebo reference="chassis">
    <material>Gazebo/Blue</material>
  </gazebo>
  <gazebo reference="rl_wheel_link">
    <mu1>0.2</mu1>
    <mu2>0.2</mu2>
    <material>Gazebo/Green</material>
  </gazebo>
  <gazebo reference="rr_wheel_link">
    <mu1>0.2</mu1>
    <mu2>0.2</mu2>
    <material>Gazebo/Green</material>
  </gazebo>
  <gazebo reference="fr_wheel_link">
    <mu1>0.2</mu1>
    <mu2>0.2</mu2>
    <material>Gazebo/Green</material>
  </gazebo>
  <gazebo reference="fl_wheel_link">
    <mu1>0.2</mu1>
    <mu2>0.2</mu2>
    <material>Gazebo/Green</material>
  </gazebo>
  <!-- <gazebo reference="imu_link">
    <gravity>true</gravity>
    <material>Gazebo/Green</material>
    <sensor name="imu_sensor" type="imu">
      <always_on>true</always_on>
      <plugin filename="libgazebo_ros_imu_sensor.so" name="imu">
        <bodyName>imu_link</bodyName>
        <gaussianNoise>0.0</gaussianNoise>
        <xyzOffset>0 0 0</xyzOffset>
        <rpyOffset>0 0 0</rpyOffset>
        <frameName>imu_link</frameName>
        <initialOrientationAsReference>false</initialOrientationAsReference>
        <ros>
          <remapping>/imu/out:=/imu</remapping>
        </ros>
      </plugin>
    </sensor>
  </gazebo> -->
  <gazebo reference="lidar_link">
    <sensor name="lidar_sensor" type="gpu_lidar">
      <pose>0 0 0 0 0 0</pose>
      <topic>scan</topic>
      <update_rate>10</update_rate>
      <lidar>
        <scan>
          <horizontal>
            <samples>640</samples>
            <resolution>1</resolution>
            <min_angle>-1.396263</min_angle>
            <max_angle>1.396263</max_angle>
          </horizontal>
          <vertical>
            <samples>1</samples>
            <resolution>1</resolution>
            <min_angle>0.0</min_angle>
            <max_angle>0.0</max_angle>
          </vertical>
        </scan>
        <range>
          <min>0.08</min>
          <max>10.0</max>
          <resolution>0.01</resolution>
        </range>
      </lidar>
      <visualize>true</visualize>
    </sensor>
  </gazebo>
  <gazebo>
    <plugin filename="libgz_ros2_control-system.so" name="gz_ros2_control::GazeboSimROS2ControlPlugin">
      <parameters>/home/sayed/ros_rolling_ws/src/levibot/levibot_skidsteer/simulation/config/gz_controllers.yaml</parameters>
      <controller_manager_prefix_node_name>controller_manager</controller_manager_prefix_node_name>
      <ros>
        <remapping>/base_controller/cmd_vel_unstamped:=/cmd_vel</remapping>
        <remapping>/base_controller/odom:=/odom</remapping>
      </ros>
    </plugin>
  </gazebo>
</robot>
